2016-06-04 01:34:42,391 ERROR: Exception on /upload/ [POST] [in /home/liqiang/.virtualenvs/flask/local/lib/python2.7/site-packages/flask/app.py:1423]
Traceback (most recent call last):
  File "/home/liqiang/.virtualenvs/flask/local/lib/python2.7/site-packages/flask/app.py", line 1817, in wsgi_app
    response = self.full_dispatch_request()
  File "/home/liqiang/.virtualenvs/flask/local/lib/python2.7/site-packages/flask/app.py", line 1477, in full_dispatch_request
    rv = self.handle_user_exception(e)
  File "/home/liqiang/.virtualenvs/flask/local/lib/python2.7/site-packages/flask/app.py", line 1381, in handle_user_exception
    reraise(exc_type, exc_value, tb)
  File "/home/liqiang/.virtualenvs/flask/local/lib/python2.7/site-packages/flask/app.py", line 1475, in full_dispatch_request
    rv = self.dispatch_request()
  File "/home/liqiang/.virtualenvs/flask/local/lib/python2.7/site-packages/flask/app.py", line 1461, in dispatch_request
    return self.view_functions[rule.endpoint](**req.view_args)
  File "/home/liqiang/code/imageadmin/application/controllers/upload.py", line 50, in upload_file
    url = upload_to_sm(file.data)
  File "/home/liqiang/.virtualenvs/flask/local/lib/python2.7/site-packages/werkzeug/datastructures.py", line 2673, in __getattr__
    return getattr(self.stream, name)
AttributeError: '_io.BytesIO' object has no attribute 'data'
2016-06-04 01:35:58,064 ERROR: Exception on /upload/ [POST] [in /home/liqiang/.virtualenvs/flask/local/lib/python2.7/site-packages/flask/app.py:1423]
Traceback (most recent call last):
  File "/home/liqiang/.virtualenvs/flask/local/lib/python2.7/site-packages/flask/app.py", line 1817, in wsgi_app
    response = self.full_dispatch_request()
  File "/home/liqiang/.virtualenvs/flask/local/lib/python2.7/site-packages/flask/app.py", line 1477, in full_dispatch_request
    rv = self.handle_user_exception(e)
  File "/home/liqiang/.virtualenvs/flask/local/lib/python2.7/site-packages/flask/app.py", line 1381, in handle_user_exception
    reraise(exc_type, exc_value, tb)
  File "/home/liqiang/.virtualenvs/flask/local/lib/python2.7/site-packages/flask/app.py", line 1475, in full_dispatch_request
    rv = self.dispatch_request()
  File "/home/liqiang/.virtualenvs/flask/local/lib/python2.7/site-packages/flask/app.py", line 1461, in dispatch_request
    return self.view_functions[rule.endpoint](**req.view_args)
  File "/home/liqiang/code/imageadmin/application/controllers/upload.py", line 51, in upload_file
    url = upload_to_sm(file.data)
  File "/home/liqiang/.virtualenvs/flask/local/lib/python2.7/site-packages/werkzeug/datastructures.py", line 2673, in __getattr__
    return getattr(self.stream, name)
AttributeError: '_io.BytesIO' object has no attribute 'data'
2016-06-04 01:36:27,441 ERROR: Exception on /upload/ [POST] [in /home/liqiang/.virtualenvs/flask/local/lib/python2.7/site-packages/flask/app.py:1423]
Traceback (most recent call last):
  File "/home/liqiang/.virtualenvs/flask/local/lib/python2.7/site-packages/flask/app.py", line 1817, in wsgi_app
    response = self.full_dispatch_request()
  File "/home/liqiang/.virtualenvs/flask/local/lib/python2.7/site-packages/flask/app.py", line 1477, in full_dispatch_request
    rv = self.handle_user_exception(e)
  File "/home/liqiang/.virtualenvs/flask/local/lib/python2.7/site-packages/flask/app.py", line 1381, in handle_user_exception
    reraise(exc_type, exc_value, tb)
  File "/home/liqiang/.virtualenvs/flask/local/lib/python2.7/site-packages/flask/app.py", line 1475, in full_dispatch_request
    rv = self.dispatch_request()
  File "/home/liqiang/.virtualenvs/flask/local/lib/python2.7/site-packages/flask/app.py", line 1461, in dispatch_request
    return self.view_functions[rule.endpoint](**req.view_args)
  File "/home/liqiang/code/imageadmin/application/controllers/upload.py", line 51, in upload_file
    url = upload_to_sm(file.stream)
  File "/home/liqiang/code/imageadmin/application/controllers/upload.py", line 29, in upload_to_sm
    url1 = data1['data']['url'];
KeyError: 'data'
